<?xml version="1.0" encoding="utf-8"?>
<!-- This URDF was automatically created by SolidWorks to URDF Exporter! Originally created by Stephen Brawner (brawner@gmail.com) 
     Commit Version: 1.6.0-4-g7f85cfe  Build Version: 1.6.7995.38578
     For more information, please see http://wiki.ros.org/sw_urdf_exporter -->
<robot
  name="box_robot">
  <link
    name="base_link">
    <inertial>
      <origin
        xyz="0.0073292 0 -0.026081"
        rpy="0 0 0" />
      <mass
        value="6.1496" />
      <inertia
        ixx="0.033003"
        ixy="3.6252E-18"
        ixz="0.00094801"
        iyy="0.13231"
        iyz="5.1339E-19"
        izz="0.16208" />
    </inertial>
    <visual>
      <origin
        xyz="0 0 0"
        rpy="0 0 0" />
      <geometry>
        <mesh
          filename="package://box_robot/meshes/base_link.STL" />
      </geometry>
      <material
        name="purple">
        <color
          rgba="0.79216 0.81961 0.93333 1" />
      </material>
    </visual>
    <collision>
      <origin
        xyz="0 0 0"
        rpy="0 0 0" />
      <geometry>
        <mesh
          filename="package://box_robot/meshes/base_link.STL" />
      </geometry>
    </collision>
  </link>
  <link
    name="left_link">
    <inertial>
      <origin
        xyz="2.7756E-17 -0.016182 -5.5511E-17"
        rpy="0 0 0" />
      <mass
        value="2.4495" />
      <inertia
        ixx="0.0035949"
        ixy="-2.2565E-19"
        ixz="2.3765E-19"
        iyy="0.0062495"
        iyz="-1.9898E-20"
        izz="0.0035949" />
    </inertial>
    <visual>
      <origin
        xyz="0 0 0"
        rpy="0 0 0" />
      <geometry>
        <mesh
          filename="package://box_robot/meshes/left_link.STL" />
      </geometry>
      <material
        name="black">
        <color
          rgba="0.79216 0.81961 0.93333 1" />
      </material>
    </visual>
    <collision>
      <origin
        xyz="0 0 0"
        rpy="0 0 0" />
      <geometry>
        <mesh
          filename="package://box_robot/meshes/left_link.STL" />
      </geometry>
    </collision>
  </link>
  <joint
    name="left_joint"
    type="continuous">
    <origin
      xyz="-0.1 0.15 -0.025"
      rpy="0 0 0" />
    <parent
      link="base_link" />
    <child
      link="left_link" />
    <axis
      xyz="0 1 0" />
    <limit
      effort="1"
      velocity="1" />
  </joint>
  <link
    name="right_link">
    <inertial>
      <origin
        xyz="2.7756E-17 0.016182 -5.5511E-17"
        rpy="0 0 0" />
      <mass
        value="2.4495" />
      <inertia
        ixx="0.0035949"
        ixy="-1.6587E-19"
        ixz="6.452E-21"
        iyy="0.0062495"
        iyz="-5.3555E-20"
        izz="0.0035949" />
    </inertial>
    <visual>
      <origin
        xyz="0 0 0"
        rpy="0 0 0" />
      <geometry>
        <mesh
          filename="package://box_robot/meshes/right_link.STL" />
      </geometry>
      <material
        name="black">
        <color
          rgba="0.79216 0.81961 0.93333 1" />
      </material>
    </visual>
    <collision>
      <origin
        xyz="0 0 0"
        rpy="0 0 0" />
      <geometry>
        <mesh
          filename="package://box_robot/meshes/right_link.STL" />
      </geometry>
    </collision>
  </link>
  <joint
    name="right_joint"
    type="continuous">
    <origin
      xyz="-0.1 -0.15 -0.025"
      rpy="0 0 0" />
    <parent
      link="base_link" />
    <child
      link="right_link" />
    <axis
      xyz="0 1 0" />
    <limit
      effort="1"
      velocity="1" />
  </joint>
  <link
  name="sensor_link">
  <inertial>
    <origin
      xyz="-6.9389E-18 0 -0.0375"
      rpy="0 0 0" />
    <mass
      value="1.1781" />
    <inertia
      ixx="0.0012885"
      ixy="5.9292E-20"
      ixz="-3.3881E-20"
      iyy="0.0012885"
      iyz="-2.7498E-35"
      izz="0.0014726" />
  </inertial>
  <visual>
    <origin
      xyz="0 0 0"
      rpy="0 0 0" />
    <geometry>
      <mesh
        filename="package://box_robot/meshes/sensor_link.STL" />
    </geometry>
    <material
      name="white">
      <color
        rgba="0.79216 0.81961 0.93333 1" />
    </material>
  </visual>
  <collision>
    <origin
      xyz="0 0 0"
      rpy="0 0 0" />
    <geometry>
      <mesh
        filename="package://box_robot/meshes/sensor_link.STL" />
    </geometry>
  </collision>
</link>
<joint
  name="sensor_joint"
  type="fixed">
  <origin
    xyz="0.15 0 0.075"
    rpy="0 0 0" />
  <parent
    link="base_link" />
  <child
    link="sensor_link" />
  <axis
    xyz="0 0 0" />
  <limit
    effort="1"
    velocity="1" />
</joint>
  <gazebo>
    <plugin name="differential_drive_controller" filename="libgazebo_ros_diff_drive.so">
      <updateRate>100</updateRate>
      <leftJoint>left_joint</leftJoint>
      <rightJoint>right_joint</rightJoint>
      <wheelSeparation>0.3</wheelSeparation>
      <wheelDiameter>0.15</wheelDiameter>
      <commandTopic>cmd_vel</commandTopic>
      <odometryTopic>odom</odometryTopic>
      <odometryFrame>odom</odometryFrame>
      <robotBaseFrame>base_link</robotBaseFrame>
      <legacyMode>false</legacyMode>
      <alwaysOn>true</alwaysOn>
      <torque>0</torque>
    </plugin>
  </gazebo>
  <gazebo reference="sensor_link">
    <sensor type="ray" name="head_hokuyo_sensor">
      <pose>0 0 0 0 0 0</pose>
      <visualize>true</visualize>
      <update_rate>20</update_rate>
      <ray>
        <scan>
          <horizontal>
            <samples>720</samples>
            <resolution>1</resolution>
            <min_angle>-1.570796</min_angle>
            <max_angle>1.570796</max_angle>
          </horizontal>
        </scan>
        <range>
          <min>0.10</min>
          <max>10.0</max>
          <resolution>0.01</resolution>
        </range>
        <noise>
          <type>gaussian</type>
          <mean>0.0</mean>
          <stddev>0.01</stddev>
        </noise>
      </ray>
      <plugin name="gazebo_ros_head_hokuyo_controller" filename="libgazebo_ros_laser.so">
        <topicName>/box_robot/laser/scan</topicName>
        <frameName>sensor_link</frameName>
      </plugin>
    </sensor>
  </gazebo>
  <gazebo reference="base_link">
    <material>Gazebo/Purple</material>
  </gazebo>
  <gazebo reference="left_link">
    <material>Gazebo/Black</material>
  </gazebo>
  <gazebo reference="right_link">
    <material>Gazebo/Black</material>
  </gazebo>
  <gazebo reference="sensor_link">
    <material>Gazebo/White</material>
  </gazebo>
  <material name="black">
    <color rgba="0.0 0.0 0.0 1.0"/>
  </material>
  <material name="blue">
    <color rgba="0.203125 0.23828125 0.28515625 1.0"/>
  </material>
  <material name="green">
    <color rgba="0.0 0.8 0.0 1.0"/>
  </material>
  <material name="grey">
    <color rgba="0.2 0.2 0.2 1.0"/>
  </material>
  <material name="orange">
    <color rgba="1.0 0.423529411765 0.0392156862745 1.0"/>
  </material>
  <material name="brown">
    <color rgba="0.870588235294 0.811764705882 0.764705882353 1.0"/>
  </material>
  <material name="red">
    <color rgba="0.80078125 0.12890625 0.1328125 1.0"/>
  </material>
  <material name="white">
    <color rgba="1 1 1 1.0"/>
  </material>
  <material name="purple">
    <color rgba="0.80078125 0.12890625 0.8 1.0"/>
  </material>
</robot>